Workbook

Sheet DTrades
A1: Trade No. | B1: Date | C1: Instrument | D1: Strike | E1: Type | F1: Entry | G1: Avg Entry | H1: SL | I1: TSL | J1: Buy/ Sell | K1: CMP | L1: Setup | M1: Base Duration | N1: Initial QTY | O1: Pyramid-1 Price | P1: P-1 QTY | Q1: P-1 Date | R1: Pyramid-2 Price | S1: P-2 QTY | T1: P-2 Date | U1: Position Size | V1: Allocation | W1: SL % | X1: Exit-1 Price | Y1: Exit-1 Qty | Z1: Date | AA1: Exit-2 Price | AB1: Exit-2 Qty | AC1: Date | AD1: Exit-3 Price | AE1: Exit-3 Qty | AF1: Date | AG1: Open QTY | AH1: Exited Qty | AI1: Avg. Exit Price | AJ1: Stock Move | AK1: Open Heat | AL1: Reward: Risk | AM1: Holding Days | AN1: Position Status | AO1: Close date | AP1: Realised Amount | AQ1: P/L Rs | AR1: PF Impact | AS1: Cumm pf | AT1: Plan Followed? | AU1: Exit Trigger | AV1: Proficiency | AW1: Growth Areas | AX1: Any other Observations
A2: 1 | B2: 45839 | C2: IMFA | F2: 804.5 | G2: =IF(ISBLANK(O2), F2, (N2*F2+O2*P2+R2*S2)/(N2+P2+S2)) -> 804.5 | H2: 797 | J2: B | K2: =IFERROR(__xludf.DUMMYFUNCTION("IF(ISBLANK(C2), """", GOOGLEFINANCE(""NSE:"" & C2,""price""))"),1507.0) -> 1507 | L2: No Setup | M2: 3-4 M | N2: 50 | U2: =if(G2*N2<>0, F2*N2+O2*P2+R2*S2, "") -> 40225 | V2: =IFS(AND(B2>=DATE(2025,1,1), B2<=DATE(2025,1,31)), U2/DDashboard!$C$2, AND(B2>=DATE(2025,2,1), B2<=DATE(2025,2,28)), U2/DDashboard!$C$3, AND(B2>=DATE(2025,3,1), B2<=DATE(2025,3,31)), U2/DDashboard!$C$4, AND(B2>=DATE(2025,4,1), B2<=DATE(2025,4,30)), U2/DDashboard!$C$5,AND(B2>=DATE(2025,5,1), B2<=DATE(2025,5,31)), U2/DDashboard!$C$6,AND(B2>=DATE(2025,6,1), B2<=DATE(2025,6,30)), U2/DDashboard!$C$7,AND(B2>=DATE(2025,7,1), B2<=DATE(2025,7,31)), U2/DDashboard!$C$8,AND(B2>=DATE(2025,8,1), B2<=DATE(2025,8,31)), U2/DDashboard!$C$9,AND(B2>=DATE(2025,9,1), B2<=DATE(2025,9,30)), U2/DDashboard!$C$10,AND(B2>=DATE(2025,10,1), B2<=DATE(2025,10,31)), U2/DDashboard!$C$11,AND(B2>=DATE(2025,11,1), B2<=DATE(2025,11,30)), U2/DDashboard!$C$12, AND(B2>=DATE(2025,12,1), B2<=DATE(2025,12,31)), U2/DDashboard!$C$13, True, "") -> 0.040225 | W2: =IFS(ISBLANK(H2),"",AND(ISNUMBER(H2),J2="B"),(F2-H2)/F2,AND(ISNUMBER(H2), J2="S"),-(F2-H2)/F2) -> 0.0093225606 | X2: 797 | Y2: 50 | Z2: 45839 | AG2: =IF(N2+P2+S2-AH2<>0,N2+P2+S2-AH2,"") | AH2: =if(Y2+AB2+AE2<>0, Y2+AB2+AE2, "") -> 50 | AI2: =IF(ISBLANK(E2), IF(ISBLANK(X2), K2, IFERROR(IF(ISBLANK(C2),X2*Y2+AA2*AB2+AD2*AE2+AG2*K2,X2*Y2+AA2*AB2+AD2*AE2+AG2*G2)/(Y2+AB2+AE2+AG2) , "")),(X2*Y2+AA2*AB2+AD2*AE2+AG2*G2)/(Y2+AB2+AE2+AG2)) -> 797 | AJ2: =IFERROR(IF(J2="B",(AI2-G2)/G2,(G2-AI2)/G2), "") -> -0.0093225606 | AK2: =IFERROR(IFS(AND(J2="B",ISBLANK(I2)),(G2-H2)*AG2,AND(J2="B",ISNUMBER(I2)),(G2-I2)*AG2,AND(J2="S",ISBLANK(I2)),(H2-G2)*AG2,AND(J2="S",ISNUMBER(I2)),(I2-G2)*AG2),"") -> 0 | AL2: =IFERROR(AJ2/W2, "") -> -1 | AM2: =IF(AN2="", "", IF(AN2="Closed", IF(ISNUMBER(AF2), AF2-B2, IF(ISNUMBER(AC2), AC2-B2, IF(ISNUMBER(Z2), Z2-B2, "") ) ), TODAY()-B2)) -> 0 | AN2: =IF(ISBLANK(N2), "", IF((N2+P2+S2-AH2)/N2=0, "Closed", (N2+P2+S2-AH2)/(N2+P2+S2))) -> Closed | AO2: =IFS(AND(ISBLANK(AF2),ISBLANK(AC2),AN2="Closed"),Z2, AND(ISBLANK(AF2),AN2="Closed", AC2<>""),AC2,AND(AN2="Closed", AF2<>""),AF2, AN2<>"Closed", "") -> 45839 | AP2: =IF(ISBLANK(N2), "", X2*Y2+AA2*AB2+AD2*AE2) -> 39850 | AQ2: =IFS(AND(ISBLANK(D2),N2<>"",AN2="Closed",J2="B"),(AH2*AI2)-U2,AND(ISBLANK(D2),N2<>"",AN2<>"Closed",J2="B"),(X2*Y2+AA2*AB2+AD2*AE2+K2*AG2)-U2, AND(ISBLANK(D2),N2<>"",AN2="Closed",J2="S"),U2-(AH2*AI2),AND(ISBLANK(D2),N2<>"",AN2<>"Closed",J2="S"),U2-(X2*Y2+AA2*AB2+AD2*AE2+K2*AG2),AND(D2<>"",N2<>"",AH2<>"",AN2="Closed",J2="B"),(AH2*AI2)-(G2*(AG2+AH2)),AND(D2<>"",N2<>"",AH2<>"",AN2="Closed",J2="S"),(G2*(AG2+AH2))-(AH2*AI2),AND(D2<>"",N2<>"",AN2<>"Closed"),"",ISBLANK(B2),"") -> -375 | AR2: =IFS(AND(B2>=DATE(2025,1,1), B2<=DATE(2025,1,31)), AQ2/DDashboard!$C$2, AND(B2>=DATE(2025,2,1), B2<=DATE(2025,2,28)), AQ2/DDashboard!$C$3, AND(B2>=DATE(2025,3,1), B2<=DATE(2025,3,31)), AQ2/DDashboard!$C$4, AND(B2>=DATE(2025,4,1), B2<=DATE(2025,4,30)), AQ2/DDashboard!$C$5,AND(B2>=DATE(2025,5,1), B2<=DATE(2025,5,31)), AQ2/DDashboard!$C$6,AND(B2>=DATE(2025,6,1), B2<=DATE(2025,6,30)), AQ2/DDashboard!$C$7,AND(B2>=DATE(2025,7,1), B2<=DATE(2025,7,31)), AQ2/DDashboard!$C$8,AND(B2>=DATE(2025,8,1), B2<=DATE(2025,8,31)), AQ2/DDashboard!$C$9,AND(B2>=DATE(2025,9,1), B2<=DATE(2025,9,30)), AQ2/DDashboard!$C$10,AND(B2>=DATE(2025,10,1), B2<=DATE(2025,10,31)), AQ2/DDashboard!$C$11,AND(B2>=DATE(2025,11,1), B2<=DATE(2025,11,30)), AQ2/DDashboard!$C$12, AND(B2>=DATE(2025,12,1), B2<=DATE(2025,12,31)), AQ2/DDashboard!$C$13, True, "") -> -0.000375 | AS2: {=IF(ISBLANK(C2), "", SUM($AR2:AR$8) )} -> 0.003415 | AT2: FALSE | AU2: SL | AV2: Small SL | AW2: Late Entry
A3: 2 | B3: 45839 | C3: RPOWER | F3: 67.93 | G3: =IF(ISBLANK(O3), F3, (N3*F3+O3*P3+R3*S3)/(N3+P3+S3)) -> 67.93 | H3: 67 | J3: B | K3: =IFERROR(__xludf.DUMMYFUNCTION("IF(ISBLANK(C3), """", GOOGLEFINANCE(""NSE:"" & C3,""price""))"),28.36) -> 28.36 | L3: No Setup | M3: 3-4 M | N3: 1000 | U3: =if(G3*N3<>0, F3*N3+O3*P3+R3*S3, "") -> 67930 | V3: =IFS(AND(B3>=DATE(2025,1,1), B3<=DATE(2025,1,31)), U3/DDashboard!$C$2, AND(B3>=DATE(2025,2,1), B3<=DATE(2025,2,28)), U3/DDashboard!$C$3, AND(B3>=DATE(2025,3,1), B3<=DATE(2025,3,31)), U3/DDashboard!$C$4, AND(B3>=DATE(2025,4,1), B3<=DATE(2025,4,30)), U3/DDashboard!$C$5,AND(B3>=DATE(2025,5,1), B3<=DATE(2025,5,31)), U3/DDashboard!$C$6,AND(B3>=DATE(2025,6,1), B3<=DATE(2025,6,30)), U3/DDashboard!$C$7,AND(B3>=DATE(2025,7,1), B3<=DATE(2025,7,31)), U3/DDashboard!$C$8,AND(B3>=DATE(2025,8,1), B3<=DATE(2025,8,31)), U3/DDashboard!$C$9,AND(B3>=DATE(2025,9,1), B3<=DATE(2025,9,30)), U3/DDashboard!$C$10,AND(B3>=DATE(2025,10,1), B3<=DATE(2025,10,31)), U3/DDashboard!$C$11,AND(B3>=DATE(2025,11,1), B3<=DATE(2025,11,30)), U3/DDashboard!$C$12, AND(B3>=DATE(2025,12,1), B3<=DATE(2025,12,31)), U3/DDashboard!$C$13, True, "") -> 0.06793 | W3: =IFS(ISBLANK(H3),"",AND(ISNUMBER(H3),J3="B"),(F3-H3)/F3,AND(ISNUMBER(H3), J3="S"),-(F3-H3)/F3) -> 0.013690564 | X3: 68.94 | Y3: 1000 | Z3: 45839 | AG3: =IF(N3+P3+S3-AH3<>0,N3+P3+S3-AH3,"") | AH3: =if(Y3+AB3+AE3<>0, Y3+AB3+AE3, "") -> 1000 | AI3: =IF(ISBLANK(E3), IF(ISBLANK(X3), K3, IFERROR(IF(ISBLANK(C3),X3*Y3+AA3*AB3+AD3*AE3+AG3*K3,X3*Y3+AA3*AB3+AD3*AE3+AG3*G3)/(Y3+AB3+AE3+AG3) , "")),(X3*Y3+AA3*AB3+AD3*AE3+AG3*G3)/(Y3+AB3+AE3+AG3)) -> 68.94 | AJ3: =IFERROR(IF(J3="B",(AI3-G3)/G3,(G3-AI3)/G3), "") -> 0.014868247 | AK3: =IFERROR(IFS(AND(J3="B",ISBLANK(I3)),(G3-H3)*AG3,AND(J3="B",ISNUMBER(I3)),(G3-I3)*AG3,AND(J3="S",ISBLANK(I3)),(H3-G3)*AG3,AND(J3="S",ISNUMBER(I3)),(I3-G3)*AG3),"") -> 0 | AL3: =IFERROR(AJ3/W3, "") -> 1.0860215 | AM3: =IF(AN3="", "", IF(AN3="Closed", IF(ISNUMBER(AF3), AF3-B3, IF(ISNUMBER(AC3), AC3-B3, IF(ISNUMBER(Z3), Z3-B3, "") ) ), TODAY()-B3)) -> 0 | AN3: =IF(ISBLANK(N3), "", IF((N3+P3+S3-AH3)/N3=0, "Closed", (N3+P3+S3-AH3)/(N3+P3+S3))) -> Closed | AO3: =IFS(AND(ISBLANK(AF3),ISBLANK(AC3),AN3="Closed"),Z3, AND(ISBLANK(AF3),AN3="Closed", AC3<>""),AC3,AND(AN3="Closed", AF3<>""),AF3, AN3<>"Closed", "") -> 45839 | AP3: =IF(ISBLANK(N3), "", X3*Y3+AA3*AB3+AD3*AE3) -> 68940 | AQ3: =IFS(AND(ISBLANK(D3),N3<>"",AN3="Closed",J3="B"),(AH3*AI3)-U3,AND(ISBLANK(D3),N3<>"",AN3<>"Closed",J3="B"),(X3*Y3+AA3*AB3+AD3*AE3+K3*AG3)-U3, AND(ISBLANK(D3),N3<>"",AN3="Closed",J3="S"),U3-(AH3*AI3),AND(ISBLANK(D3),N3<>"",AN3<>"Closed",J3="S"),U3-(X3*Y3+AA3*AB3+AD3*AE3+K3*AG3),AND(D3<>"",N3<>"",AH3<>"",AN3="Closed",J3="B"),(AH3*AI3)-(G3*(AG3+AH3)),AND(D3<>"",N3<>"",AH3<>"",AN3="Closed",J3="S"),(G3*(AG3+AH3))-(AH3*AI3),AND(D3<>"",N3<>"",AN3<>"Closed"),"",ISBLANK(B3),"") -> 1010 | AR3: =IFS(AND(B3>=DATE(2025,1,1), B3<=DATE(2025,1,31)), AQ3/DDashboard!$C$2, AND(B3>=DATE(2025,2,1), B3<=DATE(2025,2,28)), AQ3/DDashboard!$C$3, AND(B3>=DATE(2025,3,1), B3<=DATE(2025,3,31)), AQ3/DDashboard!$C$4, AND(B3>=DATE(2025,4,1), B3<=DATE(2025,4,30)), AQ3/DDashboard!$C$5,AND(B3>=DATE(2025,5,1), B3<=DATE(2025,5,31)), AQ3/DDashboard!$C$6,AND(B3>=DATE(2025,6,1), B3<=DATE(2025,6,30)), AQ3/DDashboard!$C$7,AND(B3>=DATE(2025,7,1), B3<=DATE(2025,7,31)), AQ3/DDashboard!$C$8,AND(B3>=DATE(2025,8,1), B3<=DATE(2025,8,31)), AQ3/DDashboard!$C$9,AND(B3>=DATE(2025,9,1), B3<=DATE(2025,9,30)), AQ3/DDashboard!$C$10,AND(B3>=DATE(2025,10,1), B3<=DATE(2025,10,31)), AQ3/DDashboard!$C$11,AND(B3>=DATE(2025,11,1), B3<=DATE(2025,11,30)), AQ3/DDashboard!$C$12, AND(B3>=DATE(2025,12,1), B3<=DATE(2025,12,31)), AQ3/DDashboard!$C$13, True, "") -> 0.00101 | AS3: {=IF(ISBLANK(C3), "", SUM($AR3:AR$8) )} -> 0.00379 | AT3: TRUE | AU3: Market Pressure | AV3: Exited in Strength | AW3: Late Entry
A4: 3 | B4: 45841 | C4: AMBER | F4: 7217 | G4: =IF(ISBLANK(O4), F4, (N4*F4+O4*P4+R4*S4)/(N4+P4+S4)) -> 7217 | H4: 7050 | J4: B | K4: =IFERROR(__xludf.DUMMYFUNCTION("IF(ISBLANK(C4), """", GOOGLEFINANCE(""NSE:"" & C4,""price""))"),7843.5) -> 7843.5 | L4: Trendline | M4: 5-6 M | N4: 15 | U4: =if(G4*N4<>0, F4*N4+O4*P4+R4*S4, "") -> 108255 | V4: =IFS(AND(B4>=DATE(2025,1,1), B4<=DATE(2025,1,31)), U4/DDashboard!$C$2, AND(B4>=DATE(2025,2,1), B4<=DATE(2025,2,28)), U4/DDashboard!$C$3, AND(B4>=DATE(2025,3,1), B4<=DATE(2025,3,31)), U4/DDashboard!$C$4, AND(B4>=DATE(2025,4,1), B4<=DATE(2025,4,30)), U4/DDashboard!$C$5,AND(B4>=DATE(2025,5,1), B4<=DATE(2025,5,31)), U4/DDashboard!$C$6,AND(B4>=DATE(2025,6,1), B4<=DATE(2025,6,30)), U4/DDashboard!$C$7,AND(B4>=DATE(2025,7,1), B4<=DATE(2025,7,31)), U4/DDashboard!$C$8,AND(B4>=DATE(2025,8,1), B4<=DATE(2025,8,31)), U4/DDashboard!$C$9,AND(B4>=DATE(2025,9,1), B4<=DATE(2025,9,30)), U4/DDashboard!$C$10,AND(B4>=DATE(2025,10,1), B4<=DATE(2025,10,31)), U4/DDashboard!$C$11,AND(B4>=DATE(2025,11,1), B4<=DATE(2025,11,30)), U4/DDashboard!$C$12, AND(B4>=DATE(2025,12,1), B4<=DATE(2025,12,31)), U4/DDashboard!$C$13, True, "") -> 0.108255 | W4: =IFS(ISBLANK(H4),"",AND(ISNUMBER(H4),J4="B"),(F4-H4)/F4,AND(ISNUMBER(H4), J4="S"),-(F4-H4)/F4) -> 0.023139809 | X4: 7519 | Y4: 15 | Z4: 45846 | AG4: =IF(N4+P4+S4-AH4<>0,N4+P4+S4-AH4,"") | AH4: =if(Y4+AB4+AE4<>0, Y4+AB4+AE4, "") -> 15 | AI4: =IF(ISBLANK(E4), IF(ISBLANK(X4), K4, IFERROR(IF(ISBLANK(C4),X4*Y4+AA4*AB4+AD4*AE4+AG4*K4,X4*Y4+AA4*AB4+AD4*AE4+AG4*G4)/(Y4+AB4+AE4+AG4) , "")),(X4*Y4+AA4*AB4+AD4*AE4+AG4*G4)/(Y4+AB4+AE4+AG4)) -> 7519 | AJ4: =IFERROR(IF(J4="B",(AI4-G4)/G4,(G4-AI4)/G4), "") -> 0.041845642 | AK4: =IFERROR(IFS(AND(J4="B",ISBLANK(I4)),(G4-H4)*AG4,AND(J4="B",ISNUMBER(I4)),(G4-I4)*AG4,AND(J4="S",ISBLANK(I4)),(H4-G4)*AG4,AND(J4="S",ISNUMBER(I4)),(I4-G4)*AG4),"") -> 0 | AL4: =IFERROR(AJ4/W4, "") -> 1.8083832 | AM4: =IF(AN4="", "", IF(AN4="Closed", IF(ISNUMBER(AF4), AF4-B4, IF(ISNUMBER(AC4), AC4-B4, IF(ISNUMBER(Z4), Z4-B4, "") ) ), TODAY()-B4)) -> 5 | AN4: =IF(ISBLANK(N4), "", IF((N4+P4+S4-AH4)/N4=0, "Closed", (N4+P4+S4-AH4)/(N4+P4+S4))) -> Closed | AO4: =IFS(AND(ISBLANK(AF4),ISBLANK(AC4),AN4="Closed"),Z4, AND(ISBLANK(AF4),AN4="Closed", AC4<>""),AC4,AND(AN4="Closed", AF4<>""),AF4, AN4<>"Closed", "") -> 45846 | AP4: =IF(ISBLANK(N4), "", X4*Y4+AA4*AB4+AD4*AE4) -> 112785 | AQ4: =IFS(AND(ISBLANK(D4),N4<>"",AN4="Closed",J4="B"),(AH4*AI4)-U4,AND(ISBLANK(D4),N4<>"",AN4<>"Closed",J4="B"),(X4*Y4+AA4*AB4+AD4*AE4+K4*AG4)-U4, AND(ISBLANK(D4),N4<>"",AN4="Closed",J4="S"),U4-(AH4*AI4),AND(ISBLANK(D4),N4<>"",AN4<>"Closed",J4="S"),U4-(X4*Y4+AA4*AB4+AD4*AE4+K4*AG4),AND(D4<>"",N4<>"",AH4<>"",AN4="Closed",J4="B"),(AH4*AI4)-(G4*(AG4+AH4)),AND(D4<>"",N4<>"",AH4<>"",AN4="Closed",J4="S"),(G4*(AG4+AH4))-(AH4*AI4),AND(D4<>"",N4<>"",AN4<>"Closed"),"",ISBLANK(B4),"") -> 4530 | AR4: =IFS(AND(B4>=DATE(2025,1,1), B4<=DATE(2025,1,31)), AQ4/DDashboard!$C$2, AND(B4>=DATE(2025,2,1), B4<=DATE(2025,2,28)), AQ4/DDashboard!$C$3, AND(B4>=DATE(2025,3,1), B4<=DATE(2025,3,31)), AQ4/DDashboard!$C$4, AND(B4>=DATE(2025,4,1), B4<=DATE(2025,4,30)), AQ4/DDashboard!$C$5,AND(B4>=DATE(2025,5,1), B4<=DATE(2025,5,31)), AQ4/DDashboard!$C$6,AND(B4>=DATE(2025,6,1), B4<=DATE(2025,6,30)), AQ4/DDashboard!$C$7,AND(B4>=DATE(2025,7,1), B4<=DATE(2025,7,31)), AQ4/DDashboard!$C$8,AND(B4>=DATE(2025,8,1), B4<=DATE(2025,8,31)), AQ4/DDashboard!$C$9,AND(B4>=DATE(2025,9,1), B4<=DATE(2025,9,30)), AQ4/DDashboard!$C$10,AND(B4>=DATE(2025,10,1), B4<=DATE(2025,10,31)), AQ4/DDashboard!$C$11,AND(B4>=DATE(2025,11,1), B4<=DATE(2025,11,30)), AQ4/DDashboard!$C$12, AND(B4>=DATE(2025,12,1), B4<=DATE(2025,12,31)), AQ4/DDashboard!$C$13, True, "") -> 0.00453 | AS4: {=IF(ISBLANK(C4), "", SUM($AR4:AR$8) )} -> 0.00278 | AT4: TRUE | AU4: Emotional | AV4: Good Entry | AW4: Poor Exit
A5: 4 | B5: 45841 | C5: 63MOONS | F5: 1020 | G5: =IF(ISBLANK(O5), F5, (N5*F5+O5*P5+R5*S5)/(N5+P5+S5)) -> 1020 | H5: 1000 | J5: B | K5: =IFERROR(__xludf.DUMMYFUNCTION("IF(ISBLANK(C5), """", GOOGLEFINANCE(""NSE:"" & C5,""price""))"),727.0) -> 727 | L5: Flag | M5: 2 W | N5: 50 | U5: =if(G5*N5<>0, F5*N5+O5*P5+R5*S5, "") -> 51000 | V5: =IFS(AND(B5>=DATE(2025,1,1), B5<=DATE(2025,1,31)), U5/DDashboard!$C$2, AND(B5>=DATE(2025,2,1), B5<=DATE(2025,2,28)), U5/DDashboard!$C$3, AND(B5>=DATE(2025,3,1), B5<=DATE(2025,3,31)), U5/DDashboard!$C$4, AND(B5>=DATE(2025,4,1), B5<=DATE(2025,4,30)), U5/DDashboard!$C$5,AND(B5>=DATE(2025,5,1), B5<=DATE(2025,5,31)), U5/DDashboard!$C$6,AND(B5>=DATE(2025,6,1), B5<=DATE(2025,6,30)), U5/DDashboard!$C$7,AND(B5>=DATE(2025,7,1), B5<=DATE(2025,7,31)), U5/DDashboard!$C$8,AND(B5>=DATE(2025,8,1), B5<=DATE(2025,8,31)), U5/DDashboard!$C$9,AND(B5>=DATE(2025,9,1), B5<=DATE(2025,9,30)), U5/DDashboard!$C$10,AND(B5>=DATE(2025,10,1), B5<=DATE(2025,10,31)), U5/DDashboard!$C$11,AND(B5>=DATE(2025,11,1), B5<=DATE(2025,11,30)), U5/DDashboard!$C$12, AND(B5>=DATE(2025,12,1), B5<=DATE(2025,12,31)), U5/DDashboard!$C$13, True, "") -> 0.051 | W5: =IFS(ISBLANK(H5),"",AND(ISNUMBER(H5),J5="B"),(F5-H5)/F5,AND(ISNUMBER(H5), J5="S"),-(F5-H5)/F5) -> 0.019607843 | X5: 1023 | Y5: 50 | Z5: 45841 | AG5: =IF(N5+P5+S5-AH5<>0,N5+P5+S5-AH5,"") | AH5: =if(Y5+AB5+AE5<>0, Y5+AB5+AE5, "") -> 50 | AI5: =IF(ISBLANK(E5), IF(ISBLANK(X5), K5, IFERROR(IF(ISBLANK(C5),X5*Y5+AA5*AB5+AD5*AE5+AG5*K5,X5*Y5+AA5*AB5+AD5*AE5+AG5*G5)/(Y5+AB5+AE5+AG5) , "")),(X5*Y5+AA5*AB5+AD5*AE5+AG5*G5)/(Y5+AB5+AE5+AG5)) -> 1023 | AJ5: =IFERROR(IF(J5="B",(AI5-G5)/G5,(G5-AI5)/G5), "") -> 0.0029411765 | AK5: =IFERROR(IFS(AND(J5="B",ISBLANK(I5)),(G5-H5)*AG5,AND(J5="B",ISNUMBER(I5)),(G5-I5)*AG5,AND(J5="S",ISBLANK(I5)),(H5-G5)*AG5,AND(J5="S",ISNUMBER(I5)),(I5-G5)*AG5),"") -> 0 | AL5: =IFERROR(AJ5/W5, "") -> 0.15 | AM5: =IF(AN5="", "", IF(AN5="Closed", IF(ISNUMBER(AF5), AF5-B5,IF(ISNUMBER(AC5), AC5-B5,IF(ISNUMBER(Z5), Z5-B5, ""))), TODAY()-B5)) -> 0 | AN5: =IF(ISBLANK(N5), "", IF((N5+P5+S5-AH5)/N5=0, "Closed", (N5+P5+S5-AH5)/(N5+P5+S5))) -> Closed | AO5: =IFS(AND(ISBLANK(AF5),ISBLANK(AC5),AN5="Closed"),Z5, AND(ISBLANK(AF5),AN5="Closed", AC5<>""),AC5,AND(AN5="Closed", AF5<>""),AF5, AN5<>"Closed", "") -> 45841 | AP5: =IF(ISBLANK(N5), "", X5*Y5+AA5*AB5+AD5*AE5) -> 51150 | AQ5: =IFS(AND(ISBLANK(D5),N5<>"",AN5="Closed",J5="B"),(AH5*AI5)-U5,AND(ISBLANK(D5),N5<>"",AN5<>"Closed",J5="B"),(X5*Y5+AA5*AB5+AD5*AE5+K5*AG5)-U5, AND(ISBLANK(D5),N5<>"",AN5="Closed",J5="S"),U5-(AH5*AI5),AND(ISBLANK(D5),N5<>"",AN5<>"Closed",J5="S"),U5-(X5*Y5+AA5*AB5+AD5*AE5+K5*AG5),AND(D5<>"",N5<>"",AH5<>"",AN5="Closed",J5="B"),(AH5*AI5)-(G5*(AG5+AH5)),AND(D5<>"",N5<>"",AH5<>"",AN5="Closed",J5="S"),(G5*(AG5+AH5))-(AH5*AI5),AND(D5<>"",N5<>"",AN5<>"Closed"),"",ISBLANK(B5),"") -> 150 | AR5: =IFS(AND(B5>=DATE(2025,1,1), B5<=DATE(2025,1,31)), AQ5/DDashboard!$C$2, AND(B5>=DATE(2025,2,1), B5<=DATE(2025,2,28)), AQ5/DDashboard!$C$3, AND(B5>=DATE(2025,3,1), B5<=DATE(2025,3,31)), AQ5/DDashboard!$C$4, AND(B5>=DATE(2025,4,1), B5<=DATE(2025,4,30)), AQ5/DDashboard!$C$5,AND(B5>=DATE(2025,5,1), B5<=DATE(2025,5,31)), AQ5/DDashboard!$C$6,AND(B5>=DATE(2025,6,1), B5<=DATE(2025,6,30)), AQ5/DDashboard!$C$7,AND(B5>=DATE(2025,7,1), B5<=DATE(2025,7,31)), AQ5/DDashboard!$C$8,AND(B5>=DATE(2025,8,1), B5<=DATE(2025,8,31)), AQ5/DDashboard!$C$9,AND(B5>=DATE(2025,9,1), B5<=DATE(2025,9,30)), AQ5/DDashboard!$C$10,AND(B5>=DATE(2025,10,1), B5<=DATE(2025,10,31)), AQ5/DDashboard!$C$11,AND(B5>=DATE(2025,11,1), B5<=DATE(2025,11,30)), AQ5/DDashboard!$C$12, AND(B5>=DATE(2025,12,1), B5<=DATE(2025,12,31)), AQ5/DDashboard!$C$13, True, "") -> 0.00015 | AS5: {=IF(ISBLANK(C5), "", SUM($AR5:AR$8) )} -> -0.00175 | AT5: TRUE | AU5: Emotional | AV5: Protected Breakeven | AW5: Shifted SL Quickly
A6: 5 | B6: 45841 | C6: TRANSRAILL | F6: 676 | G6: =IF(ISBLANK(O6), F6, (N6*F6+O6*P6+R6*S6)/(N6+P6+S6)) -> 676 | H6: 668 | J6: B | K6: =IFERROR(__xludf.DUMMYFUNCTION("IF(ISBLANK(C6), """", GOOGLEFINANCE(""NSE:"" & C6,""price""))"),594.0) -> 594 | L6: IPO base | M6: 5-6 M | N6: 400 | U6: =if(G6*N6<>0, F6*N6+O6*P6+R6*S6, "") -> 270400 | V6: =IFS(AND(B6>=DATE(2025,1,1), B6<=DATE(2025,1,31)), U6/DDashboard!$C$2, AND(B6>=DATE(2025,2,1), B6<=DATE(2025,2,28)), U6/DDashboard!$C$3, AND(B6>=DATE(2025,3,1), B6<=DATE(2025,3,31)), U6/DDashboard!$C$4, AND(B6>=DATE(2025,4,1), B6<=DATE(2025,4,30)), U6/DDashboard!$C$5,AND(B6>=DATE(2025,5,1), B6<=DATE(2025,5,31)), U6/DDashboard!$C$6,AND(B6>=DATE(2025,6,1), B6<=DATE(2025,6,30)), U6/DDashboard!$C$7,AND(B6>=DATE(2025,7,1), B6<=DATE(2025,7,31)), U6/DDashboard!$C$8,AND(B6>=DATE(2025,8,1), B6<=DATE(2025,8,31)), U6/DDashboard!$C$9,AND(B6>=DATE(2025,9,1), B6<=DATE(2025,9,30)), U6/DDashboard!$C$10,AND(B6>=DATE(2025,10,1), B6<=DATE(2025,10,31)), U6/DDashboard!$C$11,AND(B6>=DATE(2025,11,1), B6<=DATE(2025,11,30)), U6/DDashboard!$C$12, AND(B6>=DATE(2025,12,1), B6<=DATE(2025,12,31)), U6/DDashboard!$C$13, True, "") -> 0.2704 | W6: =IFS(ISBLANK(H6),"",AND(ISNUMBER(H6),J6="B"),(F6-H6)/F6,AND(ISNUMBER(H6), J6="S"),-(F6-H6)/F6) -> 0.01183432 | X6: 668.5 | Y6: 400 | Z6: 45841 | AG6: =IF(N6+P6+S6-AH6<>0,N6+P6+S6-AH6,"") | AH6: =if(Y6+AB6+AE6<>0, Y6+AB6+AE6, "") -> 400 | AI6: =IF(ISBLANK(E6), IF(ISBLANK(X6), K6, IFERROR(IF(ISBLANK(C6),X6*Y6+AA6*AB6+AD6*AE6+AG6*K6,X6*Y6+AA6*AB6+AD6*AE6+AG6*G6)/(Y6+AB6+AE6+AG6) , "")),(X6*Y6+AA6*AB6+AD6*AE6+AG6*G6)/(Y6+AB6+AE6+AG6)) -> 668.5 | AJ6: =IFERROR(IF(J6="B",(AI6-G6)/G6,(G6-AI6)/G6), "") -> -0.011094675 | AK6: =IFERROR(IFS(AND(J6="B",ISBLANK(I6)),(G6-H6)*AG6,AND(J6="B",ISNUMBER(I6)),(G6-I6)*AG6,AND(J6="S",ISBLANK(I6)),(H6-G6)*AG6,AND(J6="S",ISNUMBER(I6)),(I6-G6)*AG6),"") -> 0 | AL6: =IFERROR(AJ6/W6, "") -> -0.9375 | AM6: =IF(AN6="", "", IF(AN6="Closed", IF(ISNUMBER(AF6), AF6-B6, IF(ISNUMBER(AC6), AC6-B6, IF(ISNUMBER(Z6), Z6-B6, "") ) ), TODAY()-B6)) -> 0 | AN6: =IF(ISBLANK(N6), "", IF((N6+P6+S6-AH6)/N6=0, "Closed", (N6+P6+S6-AH6)/(N6+P6+S6))) -> Closed | AO6: =IFS(AND(ISBLANK(AF6),ISBLANK(AC6),AN6="Closed"),Z6, AND(ISBLANK(AF6),AN6="Closed", AC6<>""),AC6,AND(AN6="Closed", AF6<>""),AF6, AN6<>"Closed", "") -> 45841 | AP6: =IF(ISBLANK(N6), "", X6*Y6+AA6*AB6+AD6*AE6) -> 267400 | AQ6: =IFS(AND(ISBLANK(D6),N6<>"",AN6="Closed",J6="B"),(AH6*AI6)-U6,AND(ISBLANK(D6),N6<>"",AN6<>"Closed",J6="B"),(X6*Y6+AA6*AB6+AD6*AE6+K6*AG6)-U6, AND(ISBLANK(D6),N6<>"",AN6="Closed",J6="S"),U6-(AH6*AI6),AND(ISBLANK(D6),N6<>"",AN6<>"Closed",J6="S"),U6-(X6*Y6+AA6*AB6+AD6*AE6+K6*AG6),AND(D6<>"",N6<>"",AH6<>"",AN6="Closed",J6="B"),(AH6*AI6)-(G6*(AG6+AH6)),AND(D6<>"",N6<>"",AH6<>"",AN6="Closed",J6="S"),(G6*(AG6+AH6))-(AH6*AI6),AND(D6<>"",N6<>"",AN6<>"Closed"),"",ISBLANK(B6),"") -> -3000 | AR6: =IFS(AND(B6>=DATE(2025,1,1), B6<=DATE(2025,1,31)), AQ6/DDashboard!$C$2, AND(B6>=DATE(2025,2,1), B6<=DATE(2025,2,28)), AQ6/DDashboard!$C$3, AND(B6>=DATE(2025,3,1), B6<=DATE(2025,3,31)), AQ6/DDashboard!$C$4, AND(B6>=DATE(2025,4,1), B6<=DATE(2025,4,30)), AQ6/DDashboard!$C$5,AND(B6>=DATE(2025,5,1), B6<=DATE(2025,5,31)), AQ6/DDashboard!$C$6,AND(B6>=DATE(2025,6,1), B6<=DATE(2025,6,30)), AQ6/DDashboard!$C$7,AND(B6>=DATE(2025,7,1), B6<=DATE(2025,7,31)), AQ6/DDashboard!$C$8,AND(B6>=DATE(2025,8,1), B6<=DATE(2025,8,31)), AQ6/DDashboard!$C$9,AND(B6>=DATE(2025,9,1), B6<=DATE(2025,9,30)), AQ6/DDashboard!$C$10,AND(B6>=DATE(2025,10,1), B6<=DATE(2025,10,31)), AQ6/DDashboard!$C$11,AND(B6>=DATE(2025,11,1), B6<=DATE(2025,11,30)), AQ6/DDashboard!$C$12, AND(B6>=DATE(2025,12,1), B6<=DATE(2025,12,31)), AQ6/DDashboard!$C$13, True, "") -> -0.003 | AS6: {=IF(ISBLANK(C6), "", SUM($AR6:AR$8) )} -> -0.0019 | AT6: TRUE | AU6: Market Pressure | AW6: Illogical SL | AX6: This was big size trade which closed at New ATH on same day
A7: 6 | B7: 45853 | C7: DIGITIDE | F7: 234.5 | G7: =IF(ISBLANK(O7), F7, (N7*F7+O7*P7+R7*S7)/(N7+P7+S7)) -> 234.5 | H7: 231 | J7: B | K7: =IFERROR(__xludf.DUMMYFUNCTION("IF(ISBLANK(C7), """", GOOGLEFINANCE(""NSE:"" & C7,""price""))"),91.49) -> 91.49 | L7: IPO base | M7: 1 M | N7: 200 | U7: =if(G7*N7<>0, F7*N7+O7*P7+R7*S7, "") -> 46900 | V7: =IFS(AND(B7>=DATE(2025,1,1), B7<=DATE(2025,1,31)), U7/DDashboard!$C$2, AND(B7>=DATE(2025,2,1), B7<=DATE(2025,2,28)), U7/DDashboard!$C$3, AND(B7>=DATE(2025,3,1), B7<=DATE(2025,3,31)), U7/DDashboard!$C$4, AND(B7>=DATE(2025,4,1), B7<=DATE(2025,4,30)), U7/DDashboard!$C$5,AND(B7>=DATE(2025,5,1), B7<=DATE(2025,5,31)), U7/DDashboard!$C$6,AND(B7>=DATE(2025,6,1), B7<=DATE(2025,6,30)), U7/DDashboard!$C$7,AND(B7>=DATE(2025,7,1), B7<=DATE(2025,7,31)), U7/DDashboard!$C$8,AND(B7>=DATE(2025,8,1), B7<=DATE(2025,8,31)), U7/DDashboard!$C$9,AND(B7>=DATE(2025,9,1), B7<=DATE(2025,9,30)), U7/DDashboard!$C$10,AND(B7>=DATE(2025,10,1), B7<=DATE(2025,10,31)), U7/DDashboard!$C$11,AND(B7>=DATE(2025,11,1), B7<=DATE(2025,11,30)), U7/DDashboard!$C$12, AND(B7>=DATE(2025,12,1), B7<=DATE(2025,12,31)), U7/DDashboard!$C$13, True, "") -> 0.0469 | W7: =IFS(ISBLANK(H7),"",AND(ISNUMBER(H7),J7="B"),(F7-H7)/F7,AND(ISNUMBER(H7), J7="S"),-(F7-H7)/F7) -> 0.014925373 | X7: 231 | Y7: 200 | Z7: 45853 | AG7: =IF(N7+P7+S7-AH7<>0,N7+P7+S7-AH7,"") | AH7: =if(Y7+AB7+AE7<>0, Y7+AB7+AE7, "") -> 200 | AI7: =IF(ISBLANK(E7), IF(ISBLANK(X7), K7, IFERROR(IF(ISBLANK(C7),X7*Y7+AA7*AB7+AD7*AE7+AG7*K7,X7*Y7+AA7*AB7+AD7*AE7+AG7*G7)/(Y7+AB7+AE7+AG7) , "")),(X7*Y7+AA7*AB7+AD7*AE7+AG7*G7)/(Y7+AB7+AE7+AG7)) -> 231 | AJ7: =IFERROR(IF(J7="B",(AI7-G7)/G7,(G7-AI7)/G7), "") -> -0.014925373 | AK7: =IFERROR(IFS(AND(J7="B",ISBLANK(I7)),(G7-H7)*AG7,AND(J7="B",ISNUMBER(I7)),(G7-I7)*AG7,AND(J7="S",ISBLANK(I7)),(H7-G7)*AG7,AND(J7="S",ISNUMBER(I7)),(I7-G7)*AG7),"") -> 0 | AL7: =IFERROR(AJ7/W7, "") -> -1 | AM7: =IF(AN7="", "", IF(AN7="Closed", IF(ISNUMBER(AF7), AF7-B7,IF(ISNUMBER(AC7), AC7-B7,IF(ISNUMBER(Z7), Z7-B7, ""))), TODAY()-B7)) -> 0 | AN7: =IF(ISBLANK(N7), "", IF((N7+P7+S7-AH7)/N7=0, "Closed", (N7+P7+S7-AH7)/(N7+P7+S7))) -> Closed | AO7: =IFS(AND(ISBLANK(AF7),ISBLANK(AC7),AN7="Closed"),Z7, AND(ISBLANK(AF7),AN7="Closed", AC7<>""),AC7,AND(AN7="Closed", AF7<>""),AF7, AN7<>"Closed", "") -> 45853 | AP7: =IF(ISBLANK(N7), "", X7*Y7+AA7*AB7+AD7*AE7) -> 46200 | AQ7: =IFS(AND(ISBLANK(D7),N7<>"",AN7="Closed",J7="B"),(AH7*AI7)-U7,AND(ISBLANK(D7),N7<>"",AN7<>"Closed",J7="B"),(X7*Y7+AA7*AB7+AD7*AE7+K7*AG7)-U7, AND(ISBLANK(D7),N7<>"",AN7="Closed",J7="S"),U7-(AH7*AI7),AND(ISBLANK(D7),N7<>"",AN7<>"Closed",J7="S"),U7-(X7*Y7+AA7*AB7+AD7*AE7+K7*AG7),AND(D7<>"",N7<>"",AH7<>"",AN7="Closed",J7="B"),(AH7*AI7)-(G7*(AG7+AH7)),AND(D7<>"",N7<>"",AH7<>"",AN7="Closed",J7="S"),(G7*(AG7+AH7))-(AH7*AI7),AND(D7<>"",N7<>"",AN7<>"Closed"),"",ISBLANK(B7),"") -> -700 | AR7: =IFS(AND(B7>=DATE(2025,1,1), B7<=DATE(2025,1,31)), AQ7/DDashboard!$C$2, AND(B7>=DATE(2025,2,1), B7<=DATE(2025,2,28)), AQ7/DDashboard!$C$3, AND(B7>=DATE(2025,3,1), B7<=DATE(2025,3,31)), AQ7/DDashboard!$C$4, AND(B7>=DATE(2025,4,1), B7<=DATE(2025,4,30)), AQ7/DDashboard!$C$5,AND(B7>=DATE(2025,5,1), B7<=DATE(2025,5,31)), AQ7/DDashboard!$C$6,AND(B7>=DATE(2025,6,1), B7<=DATE(2025,6,30)), AQ7/DDashboard!$C$7,AND(B7>=DATE(2025,7,1), B7<=DATE(2025,7,31)), AQ7/DDashboard!$C$8,AND(B7>=DATE(2025,8,1), B7<=DATE(2025,8,31)), AQ7/DDashboard!$C$9,AND(B7>=DATE(2025,9,1), B7<=DATE(2025,9,30)), AQ7/DDashboard!$C$10,AND(B7>=DATE(2025,10,1), B7<=DATE(2025,10,31)), AQ7/DDashboard!$C$11,AND(B7>=DATE(2025,11,1), B7<=DATE(2025,11,30)), AQ7/DDashboard!$C$12, AND(B7>=DATE(2025,12,1), B7<=DATE(2025,12,31)), AQ7/DDashboard!$C$13, True, "") -> -0.0007 | AS7: {=IF(ISBLANK(C7), "", SUM($AR7:AR$8) )} -> 0.0011 | AT7: TRUE | AU7: SL | AV7: Small SL | AW7: Too Tight SL
A8: 7 | B8: 45852 | C8: WAAREEENER | F8: 3190 | G8: =IF(ISBLANK(O8), F8, (N8*F8+O8*P8+R8*S8)/(N8+P8+S8)) -> 3190 | H8: 3170 | J8: B | K8: =IFERROR(__xludf.DUMMYFUNCTION("IF(ISBLANK(C8), """", GOOGLEFINANCE(""NSE:"" & C8,""price""))"),3472.0) -> 3472 | L8: IPO base | M8: 3-4 M | N8: 20 | U8: =if(G8*N8<>0, F8*N8+O8*P8+R8*S8, "") -> 63800 | V8: =IFS(AND(B8>=DATE(2025,1,1), B8<=DATE(2025,1,31)), U8/DDashboard!$C$2, AND(B8>=DATE(2025,2,1), B8<=DATE(2025,2,28)), U8/DDashboard!$C$3, AND(B8>=DATE(2025,3,1), B8<=DATE(2025,3,31)), U8/DDashboard!$C$4, AND(B8>=DATE(2025,4,1), B8<=DATE(2025,4,30)), U8/DDashboard!$C$5,AND(B8>=DATE(2025,5,1), B8<=DATE(2025,5,31)), U8/DDashboard!$C$6,AND(B8>=DATE(2025,6,1), B8<=DATE(2025,6,30)), U8/DDashboard!$C$7,AND(B8>=DATE(2025,7,1), B8<=DATE(2025,7,31)), U8/DDashboard!$C$8,AND(B8>=DATE(2025,8,1), B8<=DATE(2025,8,31)), U8/DDashboard!$C$9,AND(B8>=DATE(2025,9,1), B8<=DATE(2025,9,30)), U8/DDashboard!$C$10,AND(B8>=DATE(2025,10,1), B8<=DATE(2025,10,31)), U8/DDashboard!$C$11,AND(B8>=DATE(2025,11,1), B8<=DATE(2025,11,30)), U8/DDashboard!$C$12, AND(B8>=DATE(2025,12,1), B8<=DATE(2025,12,31)), U8/DDashboard!$C$13, True, "") -> 0.0638 | W8: =IFS(ISBLANK(H8),"",AND(ISNUMBER(H8),J8="B"),(F8-H8)/F8,AND(ISNUMBER(H8), J8="S"),-(F8-H8)/F8) -> 0.0062695925 | X8: 3280 | Y8: 20 | Z8: 45854 | AG8: =IF(N8+P8+S8-AH8<>0,N8+P8+S8-AH8,"") | AH8: =if(Y8+AB8+AE8<>0, Y8+AB8+AE8, "") -> 20 | AI8: =IF(ISBLANK(E8), IF(ISBLANK(X8), K8, IFERROR(IF(ISBLANK(C8),X8*Y8+AA8*AB8+AD8*AE8+AG8*K8,X8*Y8+AA8*AB8+AD8*AE8+AG8*G8)/(Y8+AB8+AE8+AG8) , "")),(X8*Y8+AA8*AB8+AD8*AE8+AG8*G8)/(Y8+AB8+AE8+AG8)) -> 3280 | AJ8: =IFERROR(IF(J8="B",(AI8-G8)/G8,(G8-AI8)/G8), "") -> 0.028213166 | AK8: =IFERROR(IFS(AND(J8="B",ISBLANK(I8)),(G8-H8)*AG8,AND(J8="B",ISNUMBER(I8)),(G8-I8)*AG8,AND(J8="S",ISBLANK(I8)),(H8-G8)*AG8,AND(J8="S",ISNUMBER(I8)),(I8-G8)*AG8),"") -> 0 | AL8: =IFERROR(AJ8/W8, "") -> 4.5 | AM8: =IF(AN8="", "", IF(AN8="Closed", IF(ISNUMBER(AF8), AF8-B8, IF(ISNUMBER(AC8), AC8-B8, IF(ISNUMBER(Z8), Z8-B8, "") ) ), TODAY()-B8)) -> 2 | AN8: =IF(ISBLANK(N8), "", IF((N8+P8+S8-AH8)/N8=0, "Closed", (N8+P8+S8-AH8)/(N8+P8+S8))) -> Closed | AO8: =IFS(AND(ISBLANK(AF8),ISBLANK(AC8),AN8="Closed"),Z8, AND(ISBLANK(AF8),AN8="Closed", AC8<>""),AC8,AND(AN8="Closed", AF8<>""),AF8, AN8<>"Closed", "") -> 45854 | AP8: =IF(ISBLANK(N8), "", X8*Y8+AA8*AB8+AD8*AE8) -> 65600 | AQ8: =IFS(AND(ISBLANK(D8),N8<>"",AN8="Closed",J8="B"),(AH8*AI8)-U8,AND(ISBLANK(D8),N8<>"",AN8<>"Closed",J8="B"),(X8*Y8+AA8*AB8+AD8*AE8+K8*AG8)-U8, AND(ISBLANK(D8),N8<>"",AN8="Closed",J8="S"),U8-(AH8*AI8),AND(ISBLANK(D8),N8<>"",AN8<>"Closed",J8="S"),U8-(X8*Y8+AA8*AB8+AD8*AE8+K8*AG8),AND(D8<>"",N8<>"",AH8<>"",AN8="Closed",J8="B"),(AH8*AI8)-(G8*(AG8+AH8)),AND(D8<>"",N8<>"",AH8<>"",AN8="Closed",J8="S"),(G8*(AG8+AH8))-(AH8*AI8),AND(D8<>"",N8<>"",AN8<>"Closed"),"",ISBLANK(B8),"") -> 1800 | AR8: =IFS(AND(B8>=DATE(2025,1,1), B8<=DATE(2025,1,31)), AQ8/DDashboard!$C$2, AND(B8>=DATE(2025,2,1), B8<=DATE(2025,2,28)), AQ8/DDashboard!$C$3, AND(B8>=DATE(2025,3,1), B8<=DATE(2025,3,31)), AQ8/DDashboard!$C$4, AND(B8>=DATE(2025,4,1), B8<=DATE(2025,4,30)), AQ8/DDashboard!$C$5,AND(B8>=DATE(2025,5,1), B8<=DATE(2025,5,31)), AQ8/DDashboard!$C$6,AND(B8>=DATE(2025,6,1), B8<=DATE(2025,6,30)), AQ8/DDashboard!$C$7,AND(B8>=DATE(2025,7,1), B8<=DATE(2025,7,31)), AQ8/DDashboard!$C$8,AND(B8>=DATE(2025,8,1), B8<=DATE(2025,8,31)), AQ8/DDashboard!$C$9,AND(B8>=DATE(2025,9,1), B8<=DATE(2025,9,30)), AQ8/DDashboard!$C$10,AND(B8>=DATE(2025,10,1), B8<=DATE(2025,10,31)), AQ8/DDashboard!$C$11,AND(B8>=DATE(2025,11,1), B8<=DATE(2025,11,30)), AQ8/DDashboard!$C$12, AND(B8>=DATE(2025,12,1), B8<=DATE(2025,12,31)), AQ8/DDashboard!$C$13, True, "") -> 0.0018 | AS8: {=IF(ISBLANK(C8), "", SUM($AR8:AR$8) )} -> 0.0018 | AT8: FALSE | AU8: Emotional | AW8: Lack of Patience
A9: 8 | B9: 45852 | C9: 544441 | D9: METAINFO | F9: 242 | G9: =IF(ISBLANK(O9), F9, (N9*F9+O9*P9+R9*S9)/(N9+P9+S9)) -> 242 | H9: 193.6 | J9: B | K9: =IFERROR(__xludf.DUMMYFUNCTION("IF(ISBLANK(C9), """", GOOGLEFINANCE(""BOM:"" & C9,""price""))"),88.17) -> 88.17 | L9: Shakeout | N9: 800 | U9: =if(G9*N9<>0, F9*N9+O9*P9+R9*S9, "") -> 193600 | V9: =IFS(AND(B9>=DATE(2025,1,1), B9<=DATE(2025,1,31)), U9/DDashboard!$C$2, AND(B9>=DATE(2025,2,1), B9<=DATE(2025,2,28)), U9/DDashboard!$C$3, AND(B9>=DATE(2025,3,1), B9<=DATE(2025,3,31)), U9/DDashboard!$C$4, AND(B9>=DATE(2025,4,1), B9<=DATE(2025,4,30)), U9/DDashboard!$C$5,AND(B9>=DATE(2025,5,1), B9<=DATE(2025,5,31)), U9/DDashboard!$C$6,AND(B9>=DATE(2025,6,1), B9<=DATE(2025,6,30)), U9/DDashboard!$C$7,AND(B9>=DATE(2025,7,1), B9<=DATE(2025,7,31)), U9/DDashboard!$C$8,AND(B9>=DATE(2025,8,1), B9<=DATE(2025,8,31)), U9/DDashboard!$C$9,AND(B9>=DATE(2025,9,1), B9<=DATE(2025,9,30)), U9/DDashboard!$C$10,AND(B9>=DATE(2025,10,1), B9<=DATE(2025,10,31)), U9/DDashboard!$C$11,AND(B9>=DATE(2025,11,1), B9<=DATE(2025,11,30)), U9/DDashboard!$C$12, AND(B9>=DATE(2025,12,1), B9<=DATE(2025,12,31)), U9/DDashboard!$C$13, True, "") -> 0.1936 | W9: =IFS(ISBLANK(H9),"",AND(ISNUMBER(H9),J9="B"),(F9-H9)/F9,AND(ISNUMBER(H9), J9="S"),-(F9-H9)/F9) -> 0.2 | X9: 59 | Y9: 800 | Z9: 46111 | AG9: =IF(N9+P9+S9-AH9<>0,N9+P9+S9-AH9,"") | AH9: =if(Y9+AB9+AE9<>0, Y9+AB9+AE9, "") -> 800 | AI9: =IF(ISBLANK(E9), IF(ISBLANK(X9), K9, IFERROR(IF(ISBLANK(C9),X9*Y9+AA9*AB9+AD9*AE9+AG9*K9,X9*Y9+AA9*AB9+AD9*AE9+AG9*G9)/(Y9+AB9+AE9+AG9) , "")),(X9*Y9+AA9*AB9+AD9*AE9+AG9*G9)/(Y9+AB9+AE9+AG9)) -> 59 | AJ9: =IFERROR(IF(J9="B",(AI9-G9)/G9,(G9-AI9)/G9), "") -> -0.75619835 | AK9: =IFERROR(IFS(AND(J9="B",ISBLANK(I9)),(G9-H9)*AG9,AND(J9="B",ISNUMBER(I9)),(G9-I9)*AG9,AND(J9="S",ISBLANK(I9)),(H9-G9)*AG9,AND(J9="S",ISNUMBER(I9)),(I9-G9)*AG9),"") -> 0 | AL9: =IFERROR(AJ9/W9, "") -> -3.7809917 | AM9: =IF(AN9="", "", IF(AN9="Closed", IF(ISNUMBER(AF9), AF9-B9,IF(ISNUMBER(AC9), AC9-B9,IF(ISNUMBER(Z9), Z9-B9, ""))), TODAY()-B9)) -> 259 | AN9: =IF(ISBLANK(N9), "", IF((N9+P9+S9-AH9)/N9=0, "Closed", (N9+P9+S9-AH9)/(N9+P9+S9))) -> Closed | AO9: =IFS(AND(ISBLANK(AF9),ISBLANK(AC9),AN9="Closed"),Z9, AND(ISBLANK(AF9),AN9="Closed", AC9<>""),AC9,AND(AN9="Closed", AF9<>""),AF9, AN9<>"Closed", "") -> 46111 | AP9: =IF(ISBLANK(N9), "", X9*Y9+AA9*AB9+AD9*AE9) -> 47200 | AQ9: =IFS(AND(ISBLANK(D9),N9<>"",AN9="Closed",J9="B"),(AH9*AI9)-U9,AND(ISBLANK(D9),N9<>"",AN9<>"Closed",J9="B"),(X9*Y9+AA9*AB9+AD9*AE9+K9*AG9)-U9, AND(ISBLANK(D9),N9<>"",AN9="Closed",J9="S"),U9-(AH9*AI9),AND(ISBLANK(D9),N9<>"",AN9<>"Closed",J9="S"),U9-(X9*Y9+AA9*AB9+AD9*AE9+K9*AG9),AND(D9<>"",N9<>"",AH9<>"",AN9="Closed",J9="B"),(AH9*AI9)-(G9*(AG9+AH9)),AND(D9<>"",N9<>"",AH9<>"",AN9="Closed",J9="S"),(G9*(AG9+AH9))-(AH9*AI9),AND(D9<>"",N9<>"",AN9<>"Closed"),"",ISBLANK(B9),"") -> -146400 | AR9: =IFS(AND(B9>=DATE(2025,1,1), B9<=DATE(2025,1,31)), AQ9/DDashboard!$C$2, AND(B9>=DATE(2025,2,1), B9<=DATE(2025,2,28)), AQ9/DDashboard!$C$3, AND(B9>=DATE(2025,3,1), B9<=DATE(2025,3,31)), AQ9/DDashboard!$C$4, AND(B9>=DATE(2025,4,1), B9<=DATE(2025,4,30)), AQ9/DDashboard!$C$5,AND(B9>=DATE(2025,5,1), B9<=DATE(2025,5,31)), AQ9/DDashboard!$C$6,AND(B9>=DATE(2025,6,1), B9<=DATE(2025,6,30)), AQ9/DDashboard!$C$7,AND(B9>=DATE(2025,7,1), B9<=DATE(2025,7,31)), AQ9/DDashboard!$C$8,AND(B9>=DATE(2025,8,1), B9<=DATE(2025,8,31)), AQ9/DDashboard!$C$9,AND(B9>=DATE(2025,9,1), B9<=DATE(2025,9,30)), AQ9/DDashboard!$C$10,AND(B9>=DATE(2025,10,1), B9<=DATE(2025,10,31)), AQ9/DDashboard!$C$11,AND(B9>=DATE(2025,11,1), B9<=DATE(2025,11,30)), AQ9/DDashboard!$C$12, AND(B9>=DATE(2025,12,1), B9<=DATE(2025,12,31)), AQ9/DDashboard!$C$13, True, "") -> -0.1464 | AS9: {=IF(ISBLANK(C9), "", SUM($AR$8:AR9) )} -> -0.1446 | AT9: FALSE | AU9: Emotional
A10: 9 | B10: 45852 | C10: WAAREEENER | F10: 3190 | G10: =IF(ISBLANK(O10), F10, (N10*F10+O10*P10+R10*S10)/(N10+P10+S10)) -> 3190 | H10: 3170 | J10: B | K10: =IFERROR(__xludf.DUMMYFUNCTION("IF(ISBLANK(C10), """", GOOGLEFINANCE(""NSE:"" & C10,""price""))"),3472.0) -> 3472 | L10: IPO base | M10: 3-4 M | N10: 20 | U10: =if(G10*N10<>0, F10*N10+O10*P10+R10*S10, "") -> 63800 | V10: =IFS(AND(B10>=DATE(2025,1,1), B10<=DATE(2025,1,31)), U10/DDashboard!$C$2, AND(B10>=DATE(2025,2,1), B10<=DATE(2025,2,28)), U10/DDashboard!$C$3, AND(B10>=DATE(2025,3,1), B10<=DATE(2025,3,31)), U10/DDashboard!$C$4, AND(B10>=DATE(2025,4,1), B10<=DATE(2025,4,30)), U10/DDashboard!$C$5,AND(B10>=DATE(2025,5,1), B10<=DATE(2025,5,31)), U10/DDashboard!$C$6,AND(B10>=DATE(2025,6,1), B10<=DATE(2025,6,30)), U10/DDashboard!$C$7,AND(B10>=DATE(2025,7,1), B10<=DATE(2025,7,31)), U10/DDashboard!$C$8,AND(B10>=DATE(2025,8,1), B10<=DATE(2025,8,31)), U10/DDashboard!$C$9,AND(B10>=DATE(2025,9,1), B10<=DATE(2025,9,30)), U10/DDashboard!$C$10,AND(B10>=DATE(2025,10,1), B10<=DATE(2025,10,31)), U10/DDashboard!$C$11,AND(B10>=DATE(2025,11,1), B10<=DATE(2025,11,30)), U10/DDashboard!$C$12, AND(B10>=DATE(2025,12,1), B10<=DATE(2025,12,31)), U10/DDashboard!$C$13, True, "") -> 0.0638 | W10: =IFS(ISBLANK(H10),"",AND(ISNUMBER(H10),J10="B"),(F10-H10)/F10,AND(ISNUMBER(H10), J10="S"),-(F10-H10)/F10) -> 0.0062695925 | X10: 3280 | Y10: 20 | Z10: 45854 | AG10: =IF(N10+P10+S10-AH10<>0,N10+P10+S10-AH10,"") | AH10: =if(Y10+AB10+AE10<>0, Y10+AB10+AE10, "") -> 20 | AI10: =IF(ISBLANK(E10), IF(ISBLANK(X10), K10, IFERROR(IF(ISBLANK(C10),X10*Y10+AA10*AB10+AD10*AE10+AG10*K10,X10*Y10+AA10*AB10+AD10*AE10+AG10*G10)/(Y10+AB10+AE10+AG10) , "")),(X10*Y10+AA10*AB10+AD10*AE10+AG10*G10)/(Y10+AB10+AE10+AG10)) -> 3280 | AJ10: =IFERROR(IF(J10="B",(AI10-G10)/G10,(G10-AI10)/G10), "") -> 0.028213166 | AK10: =IFERROR(IFS(AND(J10="B",ISBLANK(I10)),(G10-H10)*AG10,AND(J10="B",ISNUMBER(I10)),(G10-I10)*AG10,AND(J10="S",ISBLANK(I10)),(H10-G10)*AG10,AND(J10="S",ISNUMBER(I10)),(I10-G10)*AG10),"") -> 0 | AL10: =IFERROR(AJ10/W10, "") -> 4.5 | AM10: =IF(AN10="", "", IF(AN10="Closed", IF(ISNUMBER(AF10), AF10-B10, IF(ISNUMBER(AC10), AC10-B10, IF(ISNUMBER(Z10), Z10-B10, "") ) ), TODAY()-B10)) -> 2 | AN10: =IF(ISBLANK(N10), "", IF((N10+P10+S10-AH10)/N10=0, "Closed", (N10+P10+S10-AH10)/(N10+P10+S10))) -> Closed | AO10: =IFS(AND(ISBLANK(AF10),ISBLANK(AC10),AN10="Closed"),Z10, AND(ISBLANK(AF10),AN10="Closed", AC10<>""),AC10,AND(AN10="Closed", AF10<>""),AF10, AN10<>"Closed", "") -> 45854 | AP10: =IF(ISBLANK(N10), "", X10*Y10+AA10*AB10+AD10*AE10) -> 65600 | AQ10: =IFS(AND(ISBLANK(D10),N10<>"",AN10="Closed",J10="B"),(AH10*AI10)-U10,AND(ISBLANK(D10),N10<>"",AN10<>"Closed",J10="B"),(X10*Y10+AA10*AB10+AD10*AE10+K10*AG10)-U10, AND(ISBLANK(D10),N10<>"",AN10="Closed",J10="S"),U10-(AH10*AI10),AND(ISBLANK(D10),N10<>"",AN10<>"Closed",J10="S"),U10-(X10*Y10+AA10*AB10+AD10*AE10+K10*AG10),AND(D10<>"",N10<>"",AH10<>"",AN10="Closed",J10="B"),(AH10*AI10)-(G10*(AG10+AH10)),AND(D10<>"",N10<>"",AH10<>"",AN10="Closed",J10="S"),(G10*(AG10+AH10))-(AH10*AI10),AND(D10<>"",N10<>"",AN10<>"Closed"),"",ISBLANK(B10),"") -> 1800 | AR10: =IFS(AND(B10>=DATE(2025,1,1), B10<=DATE(2025,1,31)), AQ10/DDashboard!$C$2, AND(B10>=DATE(2025,2,1), B10<=DATE(2025,2,28)), AQ10/DDashboard!$C$3, AND(B10>=DATE(2025,3,1), B10<=DATE(2025,3,31)), AQ10/DDashboard!$C$4, AND(B10>=DATE(2025,4,1), B10<=DATE(2025,4,30)), AQ10/DDashboard!$C$5,AND(B10>=DATE(2025,5,1), B10<=DATE(2025,5,31)), AQ10/DDashboard!$C$6,AND(B10>=DATE(2025,6,1), B10<=DATE(2025,6,30)), AQ10/DDashboard!$C$7,AND(B10>=DATE(2025,7,1), B10<=DATE(2025,7,31)), AQ10/DDashboard!$C$8,AND(B10>=DATE(2025,8,1), B10<=DATE(2025,8,31)), AQ10/DDashboard!$C$9,AND(B10>=DATE(2025,9,1), B10<=DATE(2025,9,30)), AQ10/DDashboard!$C$10,AND(B10>=DATE(2025,10,1), B10<=DATE(2025,10,31)), AQ10/DDashboard!$C$11,AND(B10>=DATE(2025,11,1), B10<=DATE(2025,11,30)), AQ10/DDashboard!$C$12, AND(B10>=DATE(2025,12,1), B10<=DATE(2025,12,31)), AQ10/DDashboard!$C$13, True, "") -> 0.0018 | AS10: {=IF(ISBLANK(C10), "", SUM($AR$8:AR10) )} -> -0.1428 | AT10: FALSE | AU10: Emotional | AW10: Lack of Patience
A11: 10 | B11: 45853 | C11: DIGITIDE | F11: 234.5 | G11: =IF(ISBLANK(O11), F11, (N11*F11+O11*P11+R11*S11)/(N11+P11+S11)) -> 234.5 | H11: 231 | J11: B | K11: =IFERROR(__xludf.DUMMYFUNCTION("IF(ISBLANK(C11), """", GOOGLEFINANCE(""NSE:"" & C11,""price""))"),91.49) -> 91.49 | L11: IPO base | M11: 1 M | N11: 200 | U11: =if(G11*N11<>0, F11*N11+O11*P11+R11*S11, "") -> 46900 | V11: =IFS(AND(B11>=DATE(2025,1,1), B11<=DATE(2025,1,31)), U11/DDashboard!$C$2, AND(B11>=DATE(2025,2,1), B11<=DATE(2025,2,28)), U11/DDashboard!$C$3, AND(B11>=DATE(2025,3,1), B11<=DATE(2025,3,31)), U11/DDashboard!$C$4, AND(B11>=DATE(2025,4,1), B11<=DATE(2025,4,30)), U11/DDashboard!$C$5,AND(B11>=DATE(2025,5,1), B11<=DATE(2025,5,31)), U11/DDashboard!$C$6,AND(B11>=DATE(2025,6,1), B11<=DATE(2025,6,30)), U11/DDashboard!$C$7,AND(B11>=DATE(2025,7,1), B11<=DATE(2025,7,31)), U11/DDashboard!$C$8,AND(B11>=DATE(2025,8,1), B11<=DATE(2025,8,31)), U11/DDashboard!$C$9,AND(B11>=DATE(2025,9,1), B11<=DATE(2025,9,30)), U11/DDashboard!$C$10,AND(B11>=DATE(2025,10,1), B11<=DATE(2025,10,31)), U11/DDashboard!$C$11,AND(B11>=DATE(2025,11,1), B11<=DATE(2025,11,30)), U11/DDashboard!$C$12, AND(B11>=DATE(2025,12,1), B11<=DATE(2025,12,31)), U11/DDashboard!$C$13, True, "") -> 0.0469 | W11: =IFS(ISBLANK(H11),"",AND(ISNUMBER(H11),J11="B"),(F11-H11)/F11,AND(ISNUMBER(H11), J11="S"),-(F11-H11)/F11) -> 0.014925373 | X11: 231 | Y11: 200 | Z11: 45853 | AG11: =IF(N11+P11+S11-AH11<>0,N11+P11+S11-AH11,"") | AH11: =if(Y11+AB11+AE11<>0, Y11+AB11+AE11, "") -> 200 | AI11: =IF(ISBLANK(E11), IF(ISBLANK(X11), K11, IFERROR(IF(ISBLANK(C11),X11*Y11+AA11*AB11+AD11*AE11+AG11*K11,X11*Y11+AA11*AB11+AD11*AE11+AG11*G11)/(Y11+AB11+AE11+AG11) , "")),(X11*Y11+AA11*AB11+AD11*AE11+AG11*G11)/(Y11+AB11+AE11+AG11)) -> 231 | AJ11: =IFERROR(IF(J11="B",(AI11-G11)/G11,(G11-AI11)/G11), "") -> -0.014925373 | AK11: =IFERROR(IFS(AND(J11="B",ISBLANK(I11)),(G11-H11)*AG11,AND(J11="B",ISNUMBER(I11)),(G11-I11)*AG11,AND(J11="S",ISBLANK(I11)),(H11-G11)*AG11,AND(J11="S",ISNUMBER(I11)),(I11-G11)*AG11),"") -> 0 | AL11: =IFERROR(AJ11/W11, "") -> -1 | AM11: =IF(AN11="", "", IF(AN11="Closed", IF(ISNUMBER(AF11), AF11-B11,IF(ISNUMBER(AC11), AC11-B11,IF(ISNUMBER(Z11), Z11-B11, ""))), TODAY()-B11)) -> 0 | AN11: =IF(ISBLANK(N11), "", IF((N11+P11+S11-AH11)/N11=0, "Closed", (N11+P11+S11-AH11)/(N11+P11+S11))) -> Closed | AO11: =IFS(AND(ISBLANK(AF11),ISBLANK(AC11),AN11="Closed"),Z11, AND(ISBLANK(AF11),AN11="Closed", AC11<>""),AC11,AND(AN11="Closed", AF11<>""),AF11, AN11<>"Closed", "") -> 45853 | AP11: =IF(ISBLANK(N11), "", X11*Y11+AA11*AB11+AD11*AE11) -> 46200 | AQ11: =IFS(AND(ISBLANK(D11),N11<>"",AN11="Closed",J11="B"),(AH11*AI11)-U11,AND(ISBLANK(D11),N11<>"",AN11<>"Closed",J11="B"),(X11*Y11+AA11*AB11+AD11*AE11+K11*AG11)-U11, AND(ISBLANK(D11),N11<>"",AN11="Closed",J11="S"),U11-(AH11*AI11),AND(ISBLANK(D11),N11<>"",AN11<>"Closed",J11="S"),U11-(X11*Y11+AA11*AB11+AD11*AE11+K11*AG11),AND(D11<>"",N11<>"",AH11<>"",AN11="Closed",J11="B"),(AH11*AI11)-(G11*(AG11+AH11)),AND(D11<>"",N11<>"",AH11<>"",AN11="Closed",J11="S"),(G11*(AG11+AH11))-(AH11*AI11),AND(D11<>"",N11<>"",AN11<>"Closed"),"",ISBLANK(B11),"") -> -700 | AR11: =IFS(AND(B11>=DATE(2025,1,1), B11<=DATE(2025,1,31)), AQ11/DDashboard!$C$2, AND(B11>=DATE(2025,2,1), B11<=DATE(2025,2,28)), AQ11/DDashboard!$C$3, AND(B11>=DATE(2025,3,1), B11<=DATE(2025,3,31)), AQ11/DDashboard!$C$4, AND(B11>=DATE(2025,4,1), B11<=DATE(2025,4,30)), AQ11/DDashboard!$C$5,AND(B11>=DATE(2025,5,1), B11<=DATE(2025,5,31)), AQ11/DDashboard!$C$6,AND(B11>=DATE(2025,6,1), B11<=DATE(2025,6,30)), AQ11/DDashboard!$C$7,AND(B11>=DATE(2025,7,1), B11<=DATE(2025,7,31)), AQ11/DDashboard!$C$8,AND(B11>=DATE(2025,8,1), B11<=DATE(2025,8,31)), AQ11/DDashboard!$C$9,AND(B11>=DATE(2025,9,1), B11<=DATE(2025,9,30)), AQ11/DDashboard!$C$10,AND(B11>=DATE(2025,10,1), B11<=DATE(2025,10,31)), AQ11/DDashboard!$C$11,AND(B11>=DATE(2025,11,1), B11<=DATE(2025,11,30)), AQ11/DDashboard!$C$12, AND(B11>=DATE(2025,12,1), B11<=DATE(2025,12,31)), AQ11/DDashboard!$C$13, True, "") -> -0.0007 | AS11: {=IF(ISBLANK(C11), "", SUM($AR$8:AR11) )} -> -0.1435 | AT11: TRUE | AU11: SL | AV11: Small SL | AW11: Too Tight SL
A12: 11 | B12: 45853 | C12: LTFOODS | F12: 486.5 | G12: =IF(ISBLANK(O12), F12, (N12*F12+O12*P12+R12*S12)/(N12+P12+S12)) -> 486.5 | H12: 480 | J12: B | K12: =IFERROR(__xludf.DUMMYFUNCTION("IF(ISBLANK(C12), """", GOOGLEFINANCE(""NSE:"" & C12,""price""))"),420.0) -> 420 | L12: Base on Base | M12: 2 W | N12: 200 | U12: =if(G12*N12<>0, F12*N12+O12*P12+R12*S12, "") -> 97300 | V12: =IFS(AND(B12>=DATE(2025,1,1), B12<=DATE(2025,1,31)), U12/DDashboard!$C$2, AND(B12>=DATE(2025,2,1), B12<=DATE(2025,2,28)), U12/DDashboard!$C$3, AND(B12>=DATE(2025,3,1), B12<=DATE(2025,3,31)), U12/DDashboard!$C$4, AND(B12>=DATE(2025,4,1), B12<=DATE(2025,4,30)), U12/DDashboard!$C$5,AND(B12>=DATE(2025,5,1), B12<=DATE(2025,5,31)), U12/DDashboard!$C$6,AND(B12>=DATE(2025,6,1), B12<=DATE(2025,6,30)), U12/DDashboard!$C$7,AND(B12>=DATE(2025,7,1), B12<=DATE(2025,7,31)), U12/DDashboard!$C$8,AND(B12>=DATE(2025,8,1), B12<=DATE(2025,8,31)), U12/DDashboard!$C$9,AND(B12>=DATE(2025,9,1), B12<=DATE(2025,9,30)), U12/DDashboard!$C$10,AND(B12>=DATE(2025,10,1), B12<=DATE(2025,10,31)), U12/DDashboard!$C$11,AND(B12>=DATE(2025,11,1), B12<=DATE(2025,11,30)), U12/DDashboard!$C$12, AND(B12>=DATE(2025,12,1), B12<=DATE(2025,12,31)), U12/DDashboard!$C$13, True, "") -> 0.0973 | W12: =IFS(ISBLANK(H12),"",AND(ISNUMBER(H12),J12="B"),(F12-H12)/F12,AND(ISNUMBER(H12), J12="S"),-(F12-H12)/F12) -> 0.01336074 | X12: 501.5 | Y12: 200 | Z12: 45856 | AG12: =IF(N12+P12+S12-AH12<>0,N12+P12+S12-AH12,"") | AH12: =if(Y12+AB12+AE12<>0, Y12+AB12+AE12, "") -> 200 | AI12: =IF(ISBLANK(E12), IF(ISBLANK(X12), K12, IFERROR(IF(ISBLANK(C12),X12*Y12+AA12*AB12+AD12*AE12+AG12*K12,X12*Y12+AA12*AB12+AD12*AE12+AG12*G12)/(Y12+AB12+AE12+AG12) , "")),(X12*Y12+AA12*AB12+AD12*AE12+AG12*G12)/(Y12+AB12+AE12+AG12)) -> 501.5 | AJ12: =IFERROR(IF(J12="B",(AI12-G12)/G12,(G12-AI12)/G12), "") -> 0.030832477 | AK12: =IFERROR(IFS(AND(J12="B",ISBLANK(I12)),(G12-H12)*AG12,AND(J12="B",ISNUMBER(I12)),(G12-I12)*AG12,AND(J12="S",ISBLANK(I12)),(H12-G12)*AG12,AND(J12="S",ISNUMBER(I12)),(I12-G12)*AG12),"") -> 0 | AL12: =IFERROR(AJ12/W12, "") -> 2.3076923 | AM12: =IF(AN12="", "", IF(AN12="Closed", IF(ISNUMBER(AF12), AF12-B12,IF(ISNUMBER(AC12), AC12-B12,IF(ISNUMBER(Z12), Z12-B12, ""))), TODAY()-B12)) -> 3 | AN12: =IF(ISBLANK(N12), "", IF((N12+P12+S12-AH12)/N12=0, "Closed", (N12+P12+S12-AH12)/(N12+P12+S12))) -> Closed | AO12: =IFS(AND(ISBLANK(AF12),ISBLANK(AC12),AN12="Closed"),Z12, AND(ISBLANK(AF12),AN12="Closed", AC12<>""),AC12,AND(AN12="Closed", AF12<>""),AF12, AN12<>"Closed", "") -> 45856 | AP12: =IF(ISBLANK(N12), "", X12*Y12+AA12*AB12+AD12*AE12) -> 100300 | AQ12: =IFS(AND(ISBLANK(D12),N12<>"",AN12="Closed",J12="B"),(AH12*AI12)-U12,AND(ISBLANK(D12),N12<>"",AN12<>"Closed",J12="B"),(X12*Y12+AA12*AB12+AD12*AE12+K12*AG12)-U12, AND(ISBLANK(D12),N12<>"",AN12="Closed",J12="S"),U12-(AH12*AI12),AND(ISBLANK(D12),N12<>"",AN12<>"Closed",J12="S"),U12-(X12*Y12+AA12*AB12+AD12*AE12+K12*AG12),AND(D12<>"",N12<>"",AH12<>"",AN12="Closed",J12="B"),(AH12*AI12)-(G12*(AG12+AH12)),AND(D12<>"",N12<>"",AH12<>"",AN12="Closed",J12="S"),(G12*(AG12+AH12))-(AH12*AI12),AND(D12<>"",N12<>"",AN12<>"Closed"),"",ISBLANK(B12),"") -> 3000 | AR12: =IFS(AND(B12>=DATE(2025,1,1), B12<=DATE(2025,1,31)), AQ12/DDashboard!$C$2, AND(B12>=DATE(2025,2,1), B12<=DATE(2025,2,28)), AQ12/DDashboard!$C$3, AND(B12>=DATE(2025,3,1), B12<=DATE(2025,3,31)), AQ12/DDashboard!$C$4, AND(B12>=DATE(2025,4,1), B12<=DATE(2025,4,30)), AQ12/DDashboard!$C$5,AND(B12>=DATE(2025,5,1), B12<=DATE(2025,5,31)), AQ12/DDashboard!$C$6,AND(B12>=DATE(2025,6,1), B12<=DATE(2025,6,30)), AQ12/DDashboard!$C$7,AND(B12>=DATE(2025,7,1), B12<=DATE(2025,7,31)), AQ12/DDashboard!$C$8,AND(B12>=DATE(2025,8,1), B12<=DATE(2025,8,31)), AQ12/DDashboard!$C$9,AND(B12>=DATE(2025,9,1), B12<=DATE(2025,9,30)), AQ12/DDashboard!$C$10,AND(B12>=DATE(2025,10,1), B12<=DATE(2025,10,31)), AQ12/DDashboard!$C$11,AND(B12>=DATE(2025,11,1), B12<=DATE(2025,11,30)), AQ12/DDashboard!$C$12, AND(B12>=DATE(2025,12,1), B12<=DATE(2025,12,31)), AQ12/DDashboard!$C$13, True, "") -> 0.003 | AS12: {=IF(ISBLANK(C12), "", SUM($AR$8:AR12) )} -> -0.1405 | AT12: TRUE | AU12: Market Pressure | AV12: Good Entry | AW12: Poor Exit
A13: 12 | B13: 45853 | C13: SUBROS | F13: 935 | G13: =IF(ISBLANK(O13), F13, (N13*F13+O13*P13+R13*S13)/(N13+P13+S13)) -> 934.51527 | H13: 915 | J13: B | K13: =IFERROR(__xludf.DUMMYFUNCTION("IF(ISBLANK(C13), """", GOOGLEFINANCE(""NSE:"" & C13,""price""))"),786.0) -> 786 | L13: Low Cheat | M13: 1 M | N13: 135 | O13: 934 | P13: 127 | Q13: 45853 | U13: =if(G13*N13<>0, F13*N13+O13*P13+R13*S13, "") -> 244843 | V13: =IFS(AND(B13>=DATE(2025,1,1), B13<=DATE(2025,1,31)), U13/DDashboard!$C$2, AND(B13>=DATE(2025,2,1), B13<=DATE(2025,2,28)), U13/DDashboard!$C$3, AND(B13>=DATE(2025,3,1), B13<=DATE(2025,3,31)), U13/DDashboard!$C$4, AND(B13>=DATE(2025,4,1), B13<=DATE(2025,4,30)), U13/DDashboard!$C$5,AND(B13>=DATE(2025,5,1), B13<=DATE(2025,5,31)), U13/DDashboard!$C$6,AND(B13>=DATE(2025,6,1), B13<=DATE(2025,6,30)), U13/DDashboard!$C$7,AND(B13>=DATE(2025,7,1), B13<=DATE(2025,7,31)), U13/DDashboard!$C$8,AND(B13>=DATE(2025,8,1), B13<=DATE(2025,8,31)), U13/DDashboard!$C$9,AND(B13>=DATE(2025,9,1), B13<=DATE(2025,9,30)), U13/DDashboard!$C$10,AND(B13>=DATE(2025,10,1), B13<=DATE(2025,10,31)), U13/DDashboard!$C$11,AND(B13>=DATE(2025,11,1), B13<=DATE(2025,11,30)), U13/DDashboard!$C$12, AND(B13>=DATE(2025,12,1), B13<=DATE(2025,12,31)), U13/DDashboard!$C$13, True, "") -> 0.244843 | W13: =IFS(ISBLANK(H13),"",AND(ISNUMBER(H13),J13="B"),(F13-H13)/F13,AND(ISNUMBER(H13), J13="S"),-(F13-H13)/F13) -> 0.021390374 | X13: 915 | Y13: 127 | Z13: 45854 | AA13: 883 | AB13: 135 | AC13: 45856 | AG13: =IF(N13+P13+S13-AH13<>0,N13+P13+S13-AH13,"") | AH13: =if(Y13+AB13+AE13<>0, Y13+AB13+AE13, "") -> 262 | AI13: =IF(ISBLANK(E13), IF(ISBLANK(X13), K13, IFERROR(IF(ISBLANK(C13),X13*Y13+AA13*AB13+AD13*AE13+AG13*K13,X13*Y13+AA13*AB13+AD13*AE13+AG13*G13)/(Y13+AB13+AE13+AG13) , "")),(X13*Y13+AA13*AB13+AD13*AE13+AG13*G13)/(Y13+AB13+AE13+AG13)) -> 898.51145 | AJ13: =IFERROR(IF(J13="B",(AI13-G13)/G13,(G13-AI13)/G13), "") -> -0.038526729 | AK13: =IFERROR(IFS(AND(J13="B",ISBLANK(I13)),(G13-H13)*AG13,AND(J13="B",ISNUMBER(I13)),(G13-I13)*AG13,AND(J13="S",ISBLANK(I13)),(H13-G13)*AG13,AND(J13="S",ISNUMBER(I13)),(I13-G13)*AG13),"") -> 0 | AL13: =IFERROR(AJ13/W13, "") -> -1.8011246 | AM13: =IF(AN13="", "", IF(AN13="Closed", IF(ISNUMBER(AF13), AF13-B13, IF(ISNUMBER(AC13), AC13-B13, IF(ISNUMBER(Z13), Z13-B13, "") ) ), TODAY()-B13)) -> 3 | AN13: =IF(ISBLANK(N13), "", IF((N13+P13+S13-AH13)/N13=0, "Closed", (N13+P13+S13-AH13)/(N13+P13+S13))) -> Closed | AO13: =IFS(AND(ISBLANK(AF13),ISBLANK(AC13),AN13="Closed"),Z13, AND(ISBLANK(AF13),AN13="Closed", AC13<>""),AC13,AND(AN13="Closed", AF13<>""),AF13, AN13<>"Closed", "") -> 45856 | AP13: =IF(ISBLANK(N13), "", X13*Y13+AA13*AB13+AD13*AE13) -> 235410 | AQ13: =IFS(AND(ISBLANK(D13),N13<>"",AN13="Closed",J13="B"),(AH13*AI13)-U13,AND(ISBLANK(D13),N13<>"",AN13<>"Closed",J13="B"),(X13*Y13+AA13*AB13+AD13*AE13+K13*AG13)-U13, AND(ISBLANK(D13),N13<>"",AN13="Closed",J13="S"),U13-(AH13*AI13),AND(ISBLANK(D13),N13<>"",AN13<>"Closed",J13="S"),U13-(X13*Y13+AA13*AB13+AD13*AE13+K13*AG13),AND(D13<>"",N13<>"",AH13<>"",AN13="Closed",J13="B"),(AH13*AI13)-(G13*(AG13+AH13)),AND(D13<>"",N13<>"",AH13<>"",AN13="Closed",J13="S"),(G13*(AG13+AH13))-(AH13*AI13),AND(D13<>"",N13<>"",AN13<>"Closed"),"",ISBLANK(B13),"") -> -9433 | AR13: =IFS(AND(B13>=DATE(2025,1,1), B13<=DATE(2025,1,31)), AQ13/DDashboard!$C$2, AND(B13>=DATE(2025,2,1), B13<=DATE(2025,2,28)), AQ13/DDashboard!$C$3, AND(B13>=DATE(2025,3,1), B13<=DATE(2025,3,31)), AQ13/DDashboard!$C$4, AND(B13>=DATE(2025,4,1), B13<=DATE(2025,4,30)), AQ13/DDashboard!$C$5,AND(B13>=DATE(2025,5,1), B13<=DATE(2025,5,31)), AQ13/DDashboard!$C$6,AND(B13>=DATE(2025,6,1), B13<=DATE(2025,6,30)), AQ13/DDashboard!$C$7,AND(B13>=DATE(2025,7,1), B13<=DATE(2025,7,31)), AQ13/DDashboard!$C$8,AND(B13>=DATE(2025,8,1), B13<=DATE(2025,8,31)), AQ13/DDashboard!$C$9,AND(B13>=DATE(2025,9,1), B13<=DATE(2025,9,30)), AQ13/DDashboard!$C$10,AND(B13>=DATE(2025,10,1), B13<=DATE(2025,10,31)), AQ13/DDashboard!$C$11,AND(B13>=DATE(2025,11,1), B13<=DATE(2025,11,30)), AQ13/DDashboard!$C$12, AND(B13>=DATE(2025,12,1), B13<=DATE(2025,12,31)), AQ13/DDashboard!$C$13, True, "") -> -0.009433 | AS13: {=IF(ISBLANK(C13), "", SUM($AR$8:AR13) )} -> -0.149933 | AT13: FALSE | AU13: SL | AW13: FOMO
A14: 13 | B14: 45853 | C14: BALRAMCHIN | F14: 622 | G14: =IF(ISBLANK(O14), F14, (N14*F14+O14*P14+R14*S14)/(N14+P14+S14)) -> 622 | H14: 615 | J14: B | K14: =IFERROR(__xludf.DUMMYFUNCTION("IF(ISBLANK(C14), """", GOOGLEFINANCE(""NSE:"" & C14,""price""))"),506.35) -> 506.35 | L14: OSHL | M14: 6-8 M | N14: 100 | U14: =if(G14*N14<>0, F14*N14+O14*P14+R14*S14, "") -> 62200 | V14: =IFS(AND(B14>=DATE(2025,1,1), B14<=DATE(2025,1,31)), U14/DDashboard!$C$2, AND(B14>=DATE(2025,2,1), B14<=DATE(2025,2,28)), U14/DDashboard!$C$3, AND(B14>=DATE(2025,3,1), B14<=DATE(2025,3,31)), U14/DDashboard!$C$4, AND(B14>=DATE(2025,4,1), B14<=DATE(2025,4,30)), U14/DDashboard!$C$5,AND(B14>=DATE(2025,5,1), B14<=DATE(2025,5,31)), U14/DDashboard!$C$6,AND(B14>=DATE(2025,6,1), B14<=DATE(2025,6,30)), U14/DDashboard!$C$7,AND(B14>=DATE(2025,7,1), B14<=DATE(2025,7,31)), U14/DDashboard!$C$8,AND(B14>=DATE(2025,8,1), B14<=DATE(2025,8,31)), U14/DDashboard!$C$9,AND(B14>=DATE(2025,9,1), B14<=DATE(2025,9,30)), U14/DDashboard!$C$10,AND(B14>=DATE(2025,10,1), B14<=DATE(2025,10,31)), U14/DDashboard!$C$11,AND(B14>=DATE(2025,11,1), B14<=DATE(2025,11,30)), U14/DDashboard!$C$12, AND(B14>=DATE(2025,12,1), B14<=DATE(2025,12,31)), U14/DDashboard!$C$13, True, "") -> 0.0622 | W14: =IFS(ISBLANK(H14),"",AND(ISNUMBER(H14),J14="B"),(F14-H14)/F14,AND(ISNUMBER(H14), J14="S"),-(F14-H14)/F14) -> 0.011254019 | X14: 615 | Y14: 100 | Z14: 45855 | AG14: =IF(N14+P14+S14-AH14<>0,N14+P14+S14-AH14,"") | AH14: =if(Y14+AB14+AE14<>0, Y14+AB14+AE14, "") -> 100 | AI14: =IF(ISBLANK(E14), IF(ISBLANK(X14), K14, IFERROR(IF(ISBLANK(C14),X14*Y14+AA14*AB14+AD14*AE14+AG14*K14,X14*Y14+AA14*AB14+AD14*AE14+AG14*G14)/(Y14+AB14+AE14+AG14) , "")),(X14*Y14+AA14*AB14+AD14*AE14+AG14*G14)/(Y14+AB14+AE14+AG14)) -> 615 | AJ14: =IFERROR(IF(J14="B",(AI14-G14)/G14,(G14-AI14)/G14), "") -> -0.011254019 | AK14: =IFERROR(IFS(AND(J14="B",ISBLANK(I14)),(G14-H14)*AG14,AND(J14="B",ISNUMBER(I14)),(G14-I14)*AG14,AND(J14="S",ISBLANK(I14)),(H14-G14)*AG14,AND(J14="S",ISNUMBER(I14)),(I14-G14)*AG14),"") -> 0 | AL14: =IFERROR(AJ14/W14, "") -> -1 | AM14: =IF(AN14="", "", IF(AN14="Closed", IF(ISNUMBER(AF14), AF14-B14,IF(ISNUMBER(AC14), AC14-B14,IF(ISNUMBER(Z14), Z14-B14, ""))), TODAY()-B14)) -> 2 | AN14: =IF(ISBLANK(N14), "", IF((N14+P14+S14-AH14)/N14=0, "Closed", (N14+P14+S14-AH14)/(N14+P14+S14))) -> Closed | AO14: =IFS(AND(ISBLANK(AF14),ISBLANK(AC14),AN14="Closed"),Z14, AND(ISBLANK(AF14),AN14="Closed", AC14<>""),AC14,AND(AN14="Closed", AF14<>""),AF14, AN14<>"Closed", "") -> 45855 | AP14: =IF(ISBLANK(N14), "", X14*Y14+AA14*AB14+AD14*AE14) -> 61500 | AQ14: =IFS(AND(ISBLANK(D14),N14<>"",AN14="Closed",J14="B"),(AH14*AI14)-U14,AND(ISBLANK(D14),N14<>"",AN14<>"Closed",J14="B"),(X14*Y14+AA14*AB14+AD14*AE14+K14*AG14)-U14, AND(ISBLANK(D14),N14<>"",AN14="Closed",J14="S"),U14-(AH14*AI14),AND(ISBLANK(D14),N14<>"",AN14<>"Closed",J14="S"),U14-(X14*Y14+AA14*AB14+AD14*AE14+K14*AG14),AND(D14<>"",N14<>"",AH14<>"",AN14="Closed",J14="B"),(AH14*AI14)-(G14*(AG14+AH14)),AND(D14<>"",N14<>"",AH14<>"",AN14="Closed",J14="S"),(G14*(AG14+AH14))-(AH14*AI14),AND(D14<>"",N14<>"",AN14<>"Closed"),"",ISBLANK(B14),"") -> -700 | AR14: =IFS(AND(B14>=DATE(2025,1,1), B14<=DATE(2025,1,31)), AQ14/DDashboard!$C$2, AND(B14>=DATE(2025,2,1), B14<=DATE(2025,2,28)), AQ14/DDashboard!$C$3, AND(B14>=DATE(2025,3,1), B14<=DATE(2025,3,31)), AQ14/DDashboard!$C$4, AND(B14>=DATE(2025,4,1), B14<=DATE(2025,4,30)), AQ14/DDashboard!$C$5,AND(B14>=DATE(2025,5,1), B14<=DATE(2025,5,31)), AQ14/DDashboard!$C$6,AND(B14>=DATE(2025,6,1), B14<=DATE(2025,6,30)), AQ14/DDashboard!$C$7,AND(B14>=DATE(2025,7,1), B14<=DATE(2025,7,31)), AQ14/DDashboard!$C$8,AND(B14>=DATE(2025,8,1), B14<=DATE(2025,8,31)), AQ14/DDashboard!$C$9,AND(B14>=DATE(2025,9,1), B14<=DATE(2025,9,30)), AQ14/DDashboard!$C$10,AND(B14>=DATE(2025,10,1), B14<=DATE(2025,10,31)), AQ14/DDashboard!$C$11,AND(B14>=DATE(2025,11,1), B14<=DATE(2025,11,30)), AQ14/DDashboard!$C$12, AND(B14>=DATE(2025,12,1), B14<=DATE(2025,12,31)), AQ14/DDashboard!$C$13, True, "") -> -0.0007 | AS14: {=IF(ISBLANK(C14), "", SUM($AR$8:AR14) )} -> -0.150633 | AT14: FALSE
A15: 14 | B15: 45853 | C15: OMAXE | F15: 105.4 | G15: =IF(ISBLANK(O15), F15, (N15*F15+O15*P15+R15*S15)/(N15+P15+S15)) -> 105.4 | H15: 104.4 | J15: B | K15: =IFERROR(__xludf.DUMMYFUNCTION("IF(ISBLANK(C15), """", GOOGLEFINANCE(""NSE:"" & C15,""price""))"),81.77) -> 81.77 | L15: Flag | M15: 2 M | N15: 1000 | U15: =if(G15*N15<>0, F15*N15+O15*P15+R15*S15, "") -> 105400 | V15: =IFS(AND(B15>=DATE(2025,1,1), B15<=DATE(2025,1,31)), U15/DDashboard!$C$2, AND(B15>=DATE(2025,2,1), B15<=DATE(2025,2,28)), U15/DDashboard!$C$3, AND(B15>=DATE(2025,3,1), B15<=DATE(2025,3,31)), U15/DDashboard!$C$4, AND(B15>=DATE(2025,4,1), B15<=DATE(2025,4,30)), U15/DDashboard!$C$5,AND(B15>=DATE(2025,5,1), B15<=DATE(2025,5,31)), U15/DDashboard!$C$6,AND(B15>=DATE(2025,6,1), B15<=DATE(2025,6,30)), U15/DDashboard!$C$7,AND(B15>=DATE(2025,7,1), B15<=DATE(2025,7,31)), U15/DDashboard!$C$8,AND(B15>=DATE(2025,8,1), B15<=DATE(2025,8,31)), U15/DDashboard!$C$9,AND(B15>=DATE(2025,9,1), B15<=DATE(2025,9,30)), U15/DDashboard!$C$10,AND(B15>=DATE(2025,10,1), B15<=DATE(2025,10,31)), U15/DDashboard!$C$11,AND(B15>=DATE(2025,11,1), B15<=DATE(2025,11,30)), U15/DDashboard!$C$12, AND(B15>=DATE(2025,12,1), B15<=DATE(2025,12,31)), U15/DDashboard!$C$13, True, "") -> 0.1054 | W15: =IFS(ISBLANK(H15),"",AND(ISNUMBER(H15),J15="B"),(F15-H15)/F15,AND(ISNUMBER(H15), J15="S"),-(F15-H15)/F15) -> 0.009487666 | X15: 104.95 | Y15: 1000 | Z15: 45854 | AG15: =IF(N15+P15+S15-AH15<>0,N15+P15+S15-AH15,"") | AH15: =if(Y15+AB15+AE15<>0, Y15+AB15+AE15, "") -> 1000 | AI15: =IF(ISBLANK(E15), IF(ISBLANK(X15), K15, IFERROR(IF(ISBLANK(C15),X15*Y15+AA15*AB15+AD15*AE15+AG14*K15,X15*Y15+AA15*AB15+AD15*AE15+AG14*G15)/(Y15+AB15+AE15+AG14) , "")),(X15*Y15+AA15*AB15+AD15*AE15+AG14*G15)/(Y15+AB15+AE15+AG14)) -> 104.95 | AJ15: =IFERROR(IF(J15="B",(AI15-G15)/G15,(G15-AI15)/G15), "") -> -0.0042694497 | AK15: =IFERROR(IFS(AND(J15="B",ISBLANK(I15)),(G15-H15)*AG14,AND(J15="B",ISNUMBER(I15)),(G15-I15)*AG14,AND(J15="S",ISBLANK(I15)),(H15-G15)*AG14,AND(J15="S",ISNUMBER(I15)),(I15-G15)*AG14),"") -> 0 | AL15: =IFERROR(AJ15/W15, "") -> -0.45 | AM15: =IF(AN15="", "", IF(AN15="Closed", IF(ISNUMBER(AF15), AF15-B15, IF(ISNUMBER(AC15), AC15-B15, IF(ISNUMBER(Z15), Z15-B15, "") ) ), TODAY()-B15)) -> 1 | AN15: =IF(ISBLANK(N15), "", IF((N15+P15+S15-AH15)/N15=0, "Closed", (N15+P15+S15-AH15)/(N15+P15+S15))) -> Closed | AO15: =IFS(AND(ISBLANK(AF15),ISBLANK(AC15),AN15="Closed"),Z15, AND(ISBLANK(AF15),AN15="Closed", AC15<>""),AC15,AND(AN15="Closed", AF15<>""),AF15, AN15<>"Closed", "") -> 45854 | AP15: =IF(ISBLANK(N15), "", X15*Y15+AA15*AB15+AD15*AE15) -> 104950 | AQ15: =IFS(AND(ISBLANK(D15),N15<>"",AN15="Closed",J15="B"),(AH15*AI15)-U15,AND(ISBLANK(D15),N15<>"",AN15<>"Closed",J15="B"),(X15*Y15+AA15*AB15+AD15*AE15+K15*AG14)-U15, AND(ISBLANK(D15),N15<>"",AN15="Closed",J15="S"),U15-(AH15*AI15),AND(ISBLANK(D15),N15<>"",AN15<>"Closed",J15="S"),U15-(X15*Y15+AA15*AB15+AD15*AE15+K15*AG14),AND(D15<>"",N15<>"",AH15<>"",AN15="Closed",J15="B"),(AH15*AI15)-(G15*(AG14+AH15)),AND(D15<>"",N15<>"",AH15<>"",AN15="Closed",J15="S"),(G15*(AG14+AH15))-(AH15*AI15),AND(D15<>"",N15<>"",AN15<>"Closed"),"",ISBLANK(B15),"") -> -450 | AR15: =IFS(AND(B15>=DATE(2025,1,1), B15<=DATE(2025,1,31)), AQ15/DDashboard!$C$2, AND(B15>=DATE(2025,2,1), B15<=DATE(2025,2,28)), AQ15/DDashboard!$C$3, AND(B15>=DATE(2025,3,1), B15<=DATE(2025,3,31)), AQ15/DDashboard!$C$4, AND(B15>=DATE(2025,4,1), B15<=DATE(2025,4,30)), AQ15/DDashboard!$C$5,AND(B15>=DATE(2025,5,1), B15<=DATE(2025,5,31)), AQ15/DDashboard!$C$6,AND(B15>=DATE(2025,6,1), B15<=DATE(2025,6,30)), AQ15/DDashboard!$C$7,AND(B15>=DATE(2025,7,1), B15<=DATE(2025,7,31)), AQ15/DDashboard!$C$8,AND(B15>=DATE(2025,8,1), B15<=DATE(2025,8,31)), AQ15/DDashboard!$C$9,AND(B15>=DATE(2025,9,1), B15<=DATE(2025,9,30)), AQ15/DDashboard!$C$10,AND(B15>=DATE(2025,10,1), B15<=DATE(2025,10,31)), AQ15/DDashboard!$C$11,AND(B15>=DATE(2025,11,1), B15<=DATE(2025,11,30)), AQ15/DDashboard!$C$12, AND(B15>=DATE(2025,12,1), B15<=DATE(2025,12,31)), AQ15/DDashboard!$C$13, True, "") -> -0.00045 | AS15: {=IF(ISBLANK(C15), "", SUM($AR$8:AR15) )} -> -0.151083 | AT15: FALSE
